<robot
  name="ourarm">



  <!-- make dummy joint -->

<joint name="dummy_joint" type="fixed">
    <origin xyz="0 -0.1 0.1" rpy="0 0 0" />
    <child link="base_link_to_link1"/>
    <parent link="dummy_link"/>
  </joint>



<!-- make dummy link -->

  <link name="dummy_link">

    <visual>
      <origin xyz="2.3898E-08 8.8613E-08 -0.022815"  rpy="0 0 0"/>
      <geometry>

	       <box size="1 1 0.2" />

      </geometry>
      <material name="Brown" />
    </visual>

    <collision>
      <origin xyz="2.3898E-08 8.8613E-08 -0.022815"  rpy="0 0 0"/>
      <geometry>
	       <box size="1 1 0.2" />
      </geometry>
      </collision>>

  </link>

  <gazebo reference="dummy_link">
    <material>Gazebo/White</material>
  </gazebo>



<link
    name="base_link_to_link1">
    <inertial>
      <origin
        xyz="2.3898E-08 8.8613E-08 -0.022815"
        rpy="0 0 0" />
      <mass
        value="0.58206" />
      <inertia
        ixx="100.0017297"
        ixy="102.319E-09"
        ixz="-102.0078E-11"
        iyy="100.0017293"
        iyz="-107.1169E-11"
        izz="100.0033774" />     
    </inertial>
    <visual>
      <origin
        xyz="0 0 0"
        rpy="0 0 0" />
      <geometry>
        <mesh
          filename="package://ourarm/meshes/base_link_to_link1.STL" />
      </geometry>
      <material
        name="">
        <color
          rgba="0.79216 0.81961 0.93333 1" />
      </material>
    </visual>
    <collision>
      <origin
        xyz="0 0 0"
        rpy="0 0 0" />
      <geometry>
        <mesh
          filename="package://ourarm/meshes/base_link_to_link1.STL" />
      </geometry>
    </collision>
  </link>

  <gazebo reference="base_link_to_link1">
              
    		<material>Gazebo/White</material>
  </gazebo>

 
  <link
    name="link1">
    <inertial>
      <origin
        xyz="1.0266E-06 0.0087208 0.071275"
        rpy="0 0 0" />
      <mass
        value="1.8225" />
      <inertia
        ixx="0.0079734"
        ixy="-8.4694E-07"
        ixz="-6.4777E-07"
        iyy="0.010432"
        iyz="-0.0006408"
        izz="0.0051683" />
    </inertial>
    <visual>
      <origin
        xyz="0 0 0"
        rpy="0 0 0" />
      <geometry>
        <mesh
          filename="package://ourarm/meshes/link1.STL" />
      </geometry>
      <material
        name="">
        <color
          rgba="0.79216 0.81961 0.93333 1" />
      </material>
    </visual>
    <collision>
      <origin
        xyz="0 0 0"
        rpy="0 0 0" />
      <geometry>
        <mesh
          filename="package://ourarm/meshes/link1.STL" />
      </geometry>
    </collision>
  </link>

  <gazebo reference="link1">
              
    		<material>Gazebo/Black</material>
  </gazebo>

  <joint
    name="joint1"
    type="revolute">
    <origin
      xyz="0 0 0"
      rpy="0 0 0" />
    <parent
      link="base_link_to_link1" />
    <child
      link="link1" />
    <axis
      xyz="0 0 1" />
    <limit
      lower="-2.74"
      upper="2.74"
      effort="100"
      velocity="0.8" />
  </joint>
  <link
    name="link2">
    <inertial>
      <origin
        xyz="-6.2218E-06 0.09265 0.0055911"
        rpy="0 0 0" />
      <mass
        value="1.6402" />
      <inertia
        ixx="0.011985"
        ixy="1.0785E-06"
        ixz="-2.0116E-07"
        iyy="0.0045001"
        iyz="0.0015108"
        izz="0.014267" />
    </inertial>
    <visual>
      <origin
        xyz="0 0 0"
        rpy="0 0 0" />
      <geometry>
        <mesh
          filename="package://ourarm/meshes/link2.STL" />
      </geometry>
      <material
        name="">
        <color
          rgba="0.89804 0.91765 0.92941 1" />
      </material>
    </visual>
    <collision>
      <origin
        xyz="0 0 0"
        rpy="0 0 0" />
      <geometry>
        <mesh
          filename="package://ourarm/meshes/link2.STL" />
      </geometry>
    </collision>
  </link>

  <gazebo reference="link2">

    		<material>Gazebo/Blue</material>
  </gazebo>


  <joint
    name="joint2"
    type="revolute">
    <origin
      xyz="0 -0.0106 0.1344"
      rpy="1.5708 -1.0021E-33 -4.3239E-18" />
    <parent
      link="link1" />
    <child
      link="link2" />
    <axis
      xyz="0 0 1" />
    <limit
      lower="-1.52"
      upper="1.52"
      effort="100"
      velocity="0.8" />
  </joint>
  <link
    name="link3">
    <inertial>
      <origin
        xyz="2.2468E-06 0.0054988 0.067608"
        rpy="0 0 0" />
      <mass
        value="0.85044" />
      <inertia
        ixx="0.0030469"
        ixy="-2.7891E-07"
        ixz="1.1927E-07"
        iyy="0.0036219"
        iyz="-0.00013166"
        izz="0.0013003" />
    </inertial>
    <visual>
      <origin
        xyz="0 0 0"
        rpy="0 0 0" />
      <geometry>
        <mesh
          filename="package://ourarm/meshes/link3.STL" />
      </geometry>
      <material
        name="">
        <color
          rgba="0.89804 0.91765 0.92941 1" />
      </material>
    </visual>
    <collision>
      <origin
        xyz="0 0 0"
        rpy="0 0 0" />
      <geometry>
        <mesh
          filename="package://ourarm/meshes/link3.STL" />
      </geometry>
    </collision>
  </link>

  <gazebo reference="link3">

    		<material>Gazebo/Red</material>
  </gazebo>

  <joint
    name="joint3"
    type="revolute">
    <origin
      xyz="0 0.201 -0.0106"
      rpy="-1.5708 4.3239E-18 0" />
    <parent
      link="link2" />
    <child
      link="link3" />
    <axis
      xyz="0 0 -1" />
    <limit
      lower="-1.6"
      upper="1.6"
      effort="100"
      velocity="0.8" />
  </joint>
  <link
    name="link4">
    <inertial>
      <origin
        xyz="-1.5408E-05 0.090484 -0.0071603"
        rpy="0 0 0" />
      <mass
        value="0.99398" />
      <inertia
        ixx="0.0057865"
        ixy="1.1357E-06"
        ixz="4.1161E-07"
        iyy="0.0017448"
        iyz="0.00079814"
        izz="0.0065485" />
    </inertial>
    <visual>
      <origin
        xyz="0 0 0"
        rpy="0 0 0" />
      <geometry>
        <mesh
          filename="package://ourarm/meshes/link4.STL" />
      </geometry>
      <material
        name="">
        <color
          rgba="0.89804 0.91765 0.92941 1" />
      </material>
    </visual>
    <collision>
      <origin
        xyz="0 0 0"
        rpy="0 0 0" />
      <geometry>
        <mesh
          filename="package://ourarm/meshes/link4.STL" />
      </geometry>
    </collision>
  </link>

  <gazebo reference="link4">

    		<material>Gazebo/White</material>
  </gazebo>

  <joint
    name="joint4"
    type="revolute">
    <origin
      xyz="0 -0.021 0.129"
      rpy="1.5708 0 -5.5511E-17" />
    <parent
      link="link3" />
    <child
      link="link4" />
    <axis
      xyz="0 0 -1" />
    <limit
      lower="-1.78"
      upper="1.78"
      effort="100"
      velocity="0.8" />
  </joint>
  <link
    name="link5">
    <inertial>
      <origin
        xyz="4.2635E-06 0.0054519 0.062593"
        rpy="0 0 0" />
      <mass
        value="0.74616" />
      <inertia
        ixx="0.002457"
        ixy="2.4694E-07"
        ixz="4.6969E-08"
        iyy="0.002853"
        iyz="-0.00014007"
        izz="0.0010252" />
    </inertial>
    <visual>
      <origin
        xyz="0 0 0"
        rpy="0 0 0" />
      <geometry>
        <mesh
          filename="package://ourarm/meshes/link5.STL" />
      </geometry>
      <material
        name="">
        <color
          rgba="1 0.75294 0.75294 1" />
      </material>
    </visual>
    <collision>
      <origin
        xyz="0 0 0"
        rpy="0 0 0" />
      <geometry>
        <mesh
          filename="package://ourarm/meshes/link5.STL" />
      </geometry>
    </collision>
  </link>

  <gazebo reference="link5">

    		<material>Gazebo/Black</material>
  </gazebo>

  <joint
    name="joint5"
    type="revolute">
    <origin
      xyz="0 0.19 -0.021"
      rpy="-1.5708 5.5511E-17 -5.2452E-32" />
    <parent
      link="link4" />
    <child
      link="link5" />
    <axis
      xyz="0 0 -1" />
    <limit
      lower="-2.35"
      upper="2.35"
      effort="100"
      velocity="0.8" />
  </joint>
  <link
    name="link6">
    <inertial>
      <origin
        xyz="-6.0163E-07 0.091826 -0.0020734"
        rpy="0 0 0" />
      <mass
        value="0.51521" />
      <inertia
        ixx="0.0025096"
        ixy="-1.4743E-08"
        ixz="1.7863E-07"
        iyy="0.00060996"
        iyz="0.00024098"
        izz="0.0027997" />
    </inertial>
    <visual>
      <origin
        xyz="0 0 0"
        rpy="0 0 0" />
      <geometry>
        <mesh
          filename="package://ourarm/meshes/link6.STL" />
      </geometry>
      <material
        name="">
        <color
          rgba="0.89804 0.91765 0.92941 1" />
      </material>
    </visual>
    <collision>
      <origin
        xyz="0 0 0"
        rpy="0 0 0" />
      <geometry>
        <mesh
          filename="package://ourarm/meshes/link6.STL" />
      </geometry>
    </collision>
  </link>

  <gazebo reference="link6">
                
    		<material>Gazebo/Blue</material>
  </gazebo>

  <joint
    name="joint6"
    type="revolute">
    <origin
      xyz="0 -0.015 0.124"
      rpy="1.5708 0 -2.7756E-17" />
    <parent
      link="link5" />
    <child
      link="link6" />
    <axis
      xyz="0 0 -1" />
    <limit
      lower="-1.78"
      upper="1.78"
      effort="100"
      velocity="0.8" />
  </joint>
  <link
    name="link7">
    <inertial>
      <origin
        xyz="0 -8.9802E-18 0.028684"
        rpy="0 0 0" />
      <mass
        value="0.13128" />
      <inertia
        ixx="5.7249E-05"
        ixy="-2.6646E-21"
        ixz="-7.2095E-22"
        iyy="5.7249E-05"
        iyz="1.5156E-21"
        izz="5.334E-05" />
    </inertial>
    <visual>
      <origin
        xyz="0.01756 -0.017 0.016"
        rpy="0 0 0" />
      <geometry>
        <mesh
          filename="package://ourarm/meshes/gripper.STL" />
      </geometry>
      <material
        name="">
        <color
          rgba="0.79216 0.81961 0.93333 1" />
      </material>
    </visual>
    <collision>
      <origin
        xyz="0.01756 -0.017 0.016"
        rpy="0 0 0" />
      <geometry>
        <mesh
          filename="package://ourarm/meshes/gripper.STL" />
      </geometry>
    </collision>
  </link>

  <gazebo reference="link7">
               
    		<material>Gazebo/Red</material>
  </gazebo>

  <joint
    name="joint7"
    type="revolute">
    <origin
      xyz="0 0.18 -0.015"
      rpy="-1.5708 2.7756E-17 -2.8887E-32" />
    <parent
      link="link6" />
    <child
      link="link7" />
    <axis
      xyz="0 0 -1" />
    <limit
      lower="-2.61"
      upper="2.61"
      effort="100"
      velocity="0.8" />
  </joint>


  <link
    name="link8_dummy">
      </link>

  <gazebo reference="link8_dummy">
    <material>Gazebo/White</material>
  </gazebo>

  <joint name="joint8_dummy" type="fixed">
     <parent link="link7"/>
     <child link="link8_dummy"/>
   </joint>



  <transmission name="tran1">
    <type>transmission_interface/SimpleTransmission</type>
    <joint name="joint1">
      <hardwareInterface>PositionJointInterface</hardwareInterface>
    </joint>
    <actuator name="motor1">
      <hardwareInterface>PositionJointInterface</hardwareInterface>
      <mechanicalReduction>1</mechanicalReduction>
    </actuator>
  </transmission>
  <transmission name="tran2">
    <type>transmission_interface/SimpleTransmission</type>
    <joint name="joint2">
      <hardwareInterface>PositionJointInterface</hardwareInterface>
    </joint>
    <actuator name="motor2">
      <hardwareInterface>PositionJointInterface</hardwareInterface>
      <mechanicalReduction>1</mechanicalReduction>
    </actuator>
  </transmission>
  <transmission name="tran3">
    <type>transmission_interface/SimpleTransmission</type>
    <joint name="joint3">
      <hardwareInterface>PositionJointInterface</hardwareInterface>
    </joint>
    <actuator name="motor3">
      <hardwareInterface>PositionJointInterface</hardwareInterface>
      <mechanicalReduction>1</mechanicalReduction>
    </actuator>
  </transmission>
  <transmission name="tran4">
    <type>transmission_interface/SimpleTransmission</type>
    <joint name="joint4">
      <hardwareInterface>PositionJointInterface</hardwareInterface>
    </joint>
    <actuator name="motor4">
      <hardwareInterface>PositionJointInterface</hardwareInterface>
      <mechanicalReduction>1</mechanicalReduction>
    </actuator>
  </transmission>
  <transmission name="tran5">
    <type>transmission_interface/SimpleTransmission</type>
    <joint name="joint5">
      <hardwareInterface>PositionJointInterface</hardwareInterface>
    </joint>
    <actuator name="motor5">
      <hardwareInterface>PositionJointInterface</hardwareInterface>
      <mechanicalReduction>1</mechanicalReduction>
    </actuator>
  </transmission>
  <transmission name="tran6">
    <type>transmission_interface/SimpleTransmission</type>
    <joint name="joint6">
      <hardwareInterface>PositionJointInterface</hardwareInterface>
    </joint>
    <actuator name="motor6">
      <hardwareInterface>PositionJointInterface</hardwareInterface>
      <mechanicalReduction>1</mechanicalReduction>
    </actuator>
  </transmission>
  <transmission name="tran7">
    <type>transmission_interface/SimpleTransmission</type>
    <joint name="joint7">
      <hardwareInterface>PositionJointInterface</hardwareInterface>
    </joint>
    <actuator name="motor7">
      <hardwareInterface>PositionJointInterface</hardwareInterface>
      <mechanicalReduction>1</mechanicalReduction>
    </actuator>
  </transmission>




  <!-- ros_control plugin -->
  <gazebo>
    <plugin filename="libgazebo_ros_control.so" name="gazebo_ros_control">
      <robotNamespace>/ourarm</robotNamespace>
    </plugin>
  </gazebo>




</robot>
